#VRML_SIM R2021b utf8
WorldInfo {
  coordinateSystem "NUE"
}
Viewpoint {
  orientation -0.5765073496552132 0.7552203015439366 0.3118999389698676 1.2234546996864453
  position 1.9130053610170248 1.5439955264898357 1.241692212772073
}
TexturedBackground {
}
Solid {
  scale 5 5 5
  children [
    Solid {
      children [
        Shape {
          appearance PBRAppearance {
            baseColorMap ImageTexture {
              url [
                "https://raw.githubusercontent.com/cyberbotics/webots/R2021b/projects/appearances/protos/textures/parquetry/chequered_parquetry_base_color.jpg"
              ]
            }
            roughness 1
            roughnessMap ImageTexture {
              url [
                "https://raw.githubusercontent.com/cyberbotics/webots/R2021b/projects/appearances/protos/textures/parquetry/chequered_parquetry_roughness.jpg"
              ]
            }
            metalness 0
            normalMap ImageTexture {
              url [
                "https://raw.githubusercontent.com/cyberbotics/webots/R2021b/projects/appearances/protos/textures/parquetry/chequered_parquetry_normal.jpg"
              ]
            }
            occlusionMap ImageTexture {
              url [
                "https://raw.githubusercontent.com/cyberbotics/webots/R2021b/projects/appearances/protos/textures/parquetry/chequered_parquetry_occlusion.jpg"
              ]
            }
          }
          geometry IndexedFaceSet {
            coord Coordinate {
              point [
                -0.5 0 -0.5
                0.5 0 -0.5
                -0.5 0 0.5
                0.5 0 0.5
              ]
            }
            texCoord TextureCoordinate {
              point [
                0 0
                2 0
                0 2
                2 2
              ]
            }
            coordIndex [
              0, 2, 3, 1, -1
            ]
            texCoordIndex [
              2, 0, 1, 3, -1
            ]
          }
        }
      ]
      name "floor"
      model "floor"
      boundingObject Plane {
      }
      locked TRUE
    }
    Solid {
      translation 0.505 0.05 0
      children [
        Shape {
          appearance PBRAppearance {
            baseColorMap ImageTexture {
              url [
                "https://raw.githubusercontent.com/cyberbotics/webots/R2021b/projects/appearances/protos/textures/brushed_aluminium/brushed_aluminium_base_color.jpg"
              ]
            }
            roughnessMap ImageTexture {
              url [
                "https://raw.githubusercontent.com/cyberbotics/webots/R2021b/projects/appearances/protos/textures/brushed_aluminium/brushed_aluminium_roughness.jpg"
              ]
            }
            normalMap ImageTexture {
              url [
                "https://raw.githubusercontent.com/cyberbotics/webots/R2021b/projects/appearances/protos/textures/brushed_aluminium/brushed_aluminium_normal.jpg"
              ]
            }
          }
          geometry IndexedFaceSet {
            coord Coordinate {
              point [
                -0.005 0.05 0.5
                0.005 0.05 0.5
                0.005 0.05 -0.5
                -0.005 0.05 -0.5
                -0.005 -0.05 -0.5
                0.005 -0.05 -0.5
                0.005 -0.05 0.5
                -0.005 -0.05 0.5
                -0.005 -0.05 0.5
                0.005 -0.05 0.5
                0.005 0.05 0.5
                -0.005 0.05 0.5
                0.005 -0.05 -0.5
                -0.005 -0.05 -0.5
                -0.005 0.05 -0.5
                0.005 0.05 -0.5
                -0.005 -0.05 -0.5
                -0.005 -0.05 0.5
                -0.005 0.05 0.5
                -0.005 0.05 -0.5
                0.005 -0.05 0.5
                0.005 -0.05 -0.5
                0.005 0.05 -0.5
                0.005 0.05 0.5
              ]
            }
            texCoord TextureCoordinate {
              point [
                0 0
                0.01 0
                0.01 1
                0 1
                0 0
                0.01 0
                0.01 1
                0 1
                0 0
                0.01 0
                0.01 0.1
                0 0.1
                0 0
                0.01 0
                0.01 0.1
                0 0.1
                0 0
                1 0
                1 0.1
                0 0.1
                0 0
                1 0
                1 0.1
                0 0.1
              ]
            }
            coordIndex [
              0, 1, 2, 3, -1, 4, 5, 6, 7, -1, 8, 9, 10, 11, -1, 12, 13, 14, 15, -1, 16, 17, 18, 19, -1, 20, 21, 22, 23, -1
            ]
            creaseAngle 1.5
          }
        }
      ]
      name "wall"
      model "box"
      boundingObject Box {
        size 0.01 0.1 1
      }
    }
    Solid {
      translation -0.505 0.05 0
      children [
        Shape {
          appearance PBRAppearance {
            baseColorMap ImageTexture {
              url [
                "https://raw.githubusercontent.com/cyberbotics/webots/R2021b/projects/appearances/protos/textures/brushed_aluminium/brushed_aluminium_base_color.jpg"
              ]
            }
            roughnessMap ImageTexture {
              url [
                "https://raw.githubusercontent.com/cyberbotics/webots/R2021b/projects/appearances/protos/textures/brushed_aluminium/brushed_aluminium_roughness.jpg"
              ]
            }
            normalMap ImageTexture {
              url [
                "https://raw.githubusercontent.com/cyberbotics/webots/R2021b/projects/appearances/protos/textures/brushed_aluminium/brushed_aluminium_normal.jpg"
              ]
            }
          }
          geometry IndexedFaceSet {
            coord Coordinate {
              point [
                -0.005 0.05 0.5
                0.005 0.05 0.5
                0.005 0.05 -0.5
                -0.005 0.05 -0.5
                -0.005 -0.05 -0.5
                0.005 -0.05 -0.5
                0.005 -0.05 0.5
                -0.005 -0.05 0.5
                -0.005 -0.05 0.5
                0.005 -0.05 0.5
                0.005 0.05 0.5
                -0.005 0.05 0.5
                0.005 -0.05 -0.5
                -0.005 -0.05 -0.5
                -0.005 0.05 -0.5
                0.005 0.05 -0.5
                -0.005 -0.05 -0.5
                -0.005 -0.05 0.5
                -0.005 0.05 0.5
                -0.005 0.05 -0.5
                0.005 -0.05 0.5
                0.005 -0.05 -0.5
                0.005 0.05 -0.5
                0.005 0.05 0.5
              ]
            }
            texCoord TextureCoordinate {
              point [
                0 0
                0.01 0
                0.01 1
                0 1
                0 0
                0.01 0
                0.01 1
                0 1
                0 0
                0.01 0
                0.01 0.1
                0 0.1
                0 0
                0.01 0
                0.01 0.1
                0 0.1
                0 0
                1 0
                1 0.1
                0 0.1
                0 0
                1 0
                1 0.1
                0 0.1
              ]
            }
            coordIndex [
              0, 1, 2, 3, -1, 4, 5, 6, 7, -1, 8, 9, 10, 11, -1, 12, 13, 14, 15, -1, 16, 17, 18, 19, -1, 20, 21, 22, 23, -1
            ]
            creaseAngle 1.5
          }
        }
      ]
      name "wall#2"
      model "box"
      boundingObject Box {
        size 0.01 0.1 1
      }
    }
    Solid {
      translation 0 0.05 0.505
      children [
        Shape {
          appearance PBRAppearance {
            baseColorMap ImageTexture {
              url [
                "https://raw.githubusercontent.com/cyberbotics/webots/R2021b/projects/appearances/protos/textures/brushed_aluminium/brushed_aluminium_base_color.jpg"
              ]
            }
            roughnessMap ImageTexture {
              url [
                "https://raw.githubusercontent.com/cyberbotics/webots/R2021b/projects/appearances/protos/textures/brushed_aluminium/brushed_aluminium_roughness.jpg"
              ]
            }
            normalMap ImageTexture {
              url [
                "https://raw.githubusercontent.com/cyberbotics/webots/R2021b/projects/appearances/protos/textures/brushed_aluminium/brushed_aluminium_normal.jpg"
              ]
            }
          }
          geometry IndexedFaceSet {
            coord Coordinate {
              point [
                -0.51 0.05 0.005
                0.51 0.05 0.005
                0.51 0.05 -0.005
                -0.51 0.05 -0.005
                -0.51 -0.05 -0.005
                0.51 -0.05 -0.005
                0.51 -0.05 0.005
                -0.51 -0.05 0.005
                -0.51 -0.05 0.005
                0.51 -0.05 0.005
                0.51 0.05 0.005
                -0.51 0.05 0.005
                0.51 -0.05 -0.005
                -0.51 -0.05 -0.005
                -0.51 0.05 -0.005
                0.51 0.05 -0.005
                -0.51 -0.05 -0.005
                -0.51 -0.05 0.005
                -0.51 0.05 0.005
                -0.51 0.05 -0.005
                0.51 -0.05 0.005
                0.51 -0.05 -0.005
                0.51 0.05 -0.005
                0.51 0.05 0.005
              ]
            }
            texCoord TextureCoordinate {
              point [
                0 0
                1 0
                1 0.00980392156862745
                0 0.00980392156862745
                0 0
                1 0
                1 0.00980392156862745
                0 0.00980392156862745
                0 0
                1 0
                1 0.09803921568627451
                0 0.09803921568627451
                0 0
                1 0
                1 0.09803921568627451
                0 0.09803921568627451
                0 0
                0.00980392156862745 0
                0.00980392156862745 0.09803921568627451
                0 0.09803921568627451
                0 0
                0.00980392156862745 0
                0.00980392156862745 0.09803921568627451
                0 0.09803921568627451
              ]
            }
            coordIndex [
              0, 1, 2, 3, -1, 4, 5, 6, 7, -1, 8, 9, 10, 11, -1, 12, 13, 14, 15, -1, 16, 17, 18, 19, -1, 20, 21, 22, 23, -1
            ]
            creaseAngle 1.5
          }
        }
      ]
      name "wall#3"
      model "box"
      boundingObject Box {
        size 1.02 0.1 0.01
      }
    }
    Solid {
      translation 0 0.05 -0.505
      children [
        Shape {
          appearance PBRAppearance {
            baseColorMap ImageTexture {
              url [
                "https://raw.githubusercontent.com/cyberbotics/webots/R2021b/projects/appearances/protos/textures/brushed_aluminium/brushed_aluminium_base_color.jpg"
              ]
            }
            roughnessMap ImageTexture {
              url [
                "https://raw.githubusercontent.com/cyberbotics/webots/R2021b/projects/appearances/protos/textures/brushed_aluminium/brushed_aluminium_roughness.jpg"
              ]
            }
            normalMap ImageTexture {
              url [
                "https://raw.githubusercontent.com/cyberbotics/webots/R2021b/projects/appearances/protos/textures/brushed_aluminium/brushed_aluminium_normal.jpg"
              ]
            }
          }
          geometry IndexedFaceSet {
            coord Coordinate {
              point [
                -0.51 0.05 0.005
                0.51 0.05 0.005
                0.51 0.05 -0.005
                -0.51 0.05 -0.005
                -0.51 -0.05 -0.005
                0.51 -0.05 -0.005
                0.51 -0.05 0.005
                -0.51 -0.05 0.005
                -0.51 -0.05 0.005
                0.51 -0.05 0.005
                0.51 0.05 0.005
                -0.51 0.05 0.005
                0.51 -0.05 -0.005
                -0.51 -0.05 -0.005
                -0.51 0.05 -0.005
                0.51 0.05 -0.005
                -0.51 -0.05 -0.005
                -0.51 -0.05 0.005
                -0.51 0.05 0.005
                -0.51 0.05 -0.005
                0.51 -0.05 0.005
                0.51 -0.05 -0.005
                0.51 0.05 -0.005
                0.51 0.05 0.005
              ]
            }
            texCoord TextureCoordinate {
              point [
                0 0
                1 0
                1 0.00980392156862745
                0 0.00980392156862745
                0 0
                1 0
                1 0.00980392156862745
                0 0.00980392156862745
                0 0
                1 0
                1 0.09803921568627451
                0 0.09803921568627451
                0 0
                1 0
                1 0.09803921568627451
                0 0.09803921568627451
                0 0
                0.00980392156862745 0
                0.00980392156862745 0.09803921568627451
                0 0.09803921568627451
                0 0
                0.00980392156862745 0
                0.00980392156862745 0.09803921568627451
                0 0.09803921568627451
              ]
            }
            coordIndex [
              0, 1, 2, 3, -1, 4, 5, 6, 7, -1, 8, 9, 10, 11, -1, 12, 13, 14, 15, -1, 16, 17, 18, 19, -1, 20, 21, 22, 23, -1
            ]
            creaseAngle 1.5
          }
        }
      ]
      name "wall#4"
      model "box"
      boundingObject Box {
        size 1.02 0.1 0.01
      }
    }
  ]
  name "rectangle arena"
  model "rectangle arena"
}
Robot {
  translation -8.52498317229339e-09 0.03972102168755388 1.0248877905207824e-13
  rotation 1.0220142027124738e-07 -1.3204585828881337e-05 -0.9999999999128141 9.034601390764808e-08
  children [
    DEF BODY Shape {
      appearance PBRAppearance {
        baseColor 0.917647 0.145098 0.145098
        roughness 1
        metalness 0
      }
      geometry Box {
        size 0.1 0.05 0.2
      }
    }
    DEF WHEEL1 HingeJoint {
      jointParameters HingeJointParameters {
        position 2.292031675314526e-13
        anchor 0.06 0 0.05
      }
      device [
        RotationalMotor {
          name "wheel1"
        }
      ]
      endPoint Solid {
        translation 0.06 0 0.05
        rotation 1 0 0 0
        children [
          DEF WHEEL Transform {
            rotation 0 0 1 1.5708
            children [
              Shape {
                appearance PBRAppearance {
                  baseColor 0.305882 0.898039 0.25098
                  roughness 1
                  metalness 0
                }
                geometry Cylinder {
                  height 0.02
                  radius 0.04
                  subdivision 24
                }
              }
            ]
          }
        ]
        boundingObject USE WHEEL
        physics Physics {
        }
        linearVelocity -7.125127563535944e-13 -3.3176525931388407e-07 -2.5583980963609156e-12
        angularVelocity -6.396535044811468e-11 1.593722649897697e-15 1.7810341659833342e-11
      }
    }
    DEF WHEEL2 HingeJoint {
      jointParameters HingeJointParameters {
        position -1.3182016296277862e-11
        anchor -0.06 0 0.05
      }
      device [
        RotationalMotor {
          name "wheel2"
        }
      ]
      endPoint Solid {
        translation -0.06 0 0.05
        rotation 1 0 0 0
        children [
          USE WHEEL
        ]
        name "solid(1)"
        boundingObject USE WHEEL
        physics Physics {
        }
        linearVelocity -7.125003527104151e-13 -3.317668188105893e-07 -2.5583832296475e-12
        angularVelocity -6.396717528127909e-11 1.5937216239847608e-15 1.781034165983244e-11
      }
    }
    DEF WHEEL3 HingeJoint {
      jointParameters HingeJointParameters {
        position 2.2166131637942622e-13
        anchor 0.06 0 -0.05
      }
      device [
        RotationalMotor {
          name "wheel3"
        }
      ]
      endPoint Solid {
        translation 0.06 0 -0.05
        rotation 1 0 0 0
        children [
          USE WHEEL
        ]
        name "solid(2)"
        boundingObject USE WHEEL
        physics Physics {
        }
        linearVelocity -7.124247615721571e-13 -3.3176520308873144e-07 -2.55857505918605e-12
        angularVelocity -6.397198674145731e-11 1.5937202443835266e-15 1.7803970356392648e-11
      }
    }
    DEF WHEEL4 HingeJoint {
      jointParameters HingeJointParameters {
        position -6.483055781421877e-12
        anchor -0.06 0 -0.05
      }
      device [
        RotationalMotor {
          name "wheel4"
        }
      ]
      endPoint Solid {
        translation -0.06 0 -0.05
        rotation 1 0 0 0
        children [
          USE WHEEL
        ]
        name "solid(3)"
        boundingObject USE WHEEL
        physics Physics {
        }
        linearVelocity -7.130018787648333e-13 -3.3176676371641964e-07 -2.5583293475783246e-12
        angularVelocity -6.396569682697871e-11 1.5937203423292603e-15 1.7828181309499227e-11
      }
    }
    LightSensor {
      translation 0.03 0 0.1
      rotation 0 1 0 -1.57
      children [
        Shape {
          appearance PBRAppearance {
            baseColor 0 0 1
            roughness 1
            metalness 0
          }
          geometry Box {
            size 0.01 0.01 0.01
          }
        }
      ]
      name "ls_left"
    }
    LightSensor {
      translation -0.03 0 0.1
      rotation 0 1 0 -1.57
      children [
        Shape {
          appearance PBRAppearance {
            baseColor 0 0 1
            roughness 1
            metalness 0
          }
          geometry Box {
            size 0.01 0.01 0.01
          }
        }
      ]
      name "ls_right"
    }
  ]
  boundingObject USE BODY
  physics Physics {
    density -1
    mass 1
  }
  controller "braitenberg"
}
PointLight {
  attenuation 0 0 1
  location 0 0 0.53
}
